<?xml version="1.0" encoding="utf-8"?>
<!-- This URDF was automatically created by SolidWorks to URDF Exporter! Originally created by Stephen Brawner (brawner@gmail.com) 
     Commit Version: 1.5.1-0-g916b5db  Build Version: 1.5.7152.31018
     For more information, please see http://wiki.ros.org/sw_urdf_exporter -->
<robot
  name="robot_sim">
  <link
    name="base_link">
    <inertial>
      <origin
        xyz="-0.0034292 -8.3267E-17 0.0068968"
        rpy="0 0 0" />
      <mass
        value="1.0017" />
      <inertia
        ixx="0.0044532"
        ixy="2.8047E-17"
        ixz="1.2735E-05"
        iyy="0.0017162"
        iyz="-1.2345E-17"
        izz="0.0052108" />
    </inertial>
    <visual>
      <origin
        xyz="0 0 0"
        rpy="0 0 0" />
      <geometry>
        <mesh
          filename="package://robot_sim/meshes/base_link.STL" />
      </geometry>
      <material
        name="green">
        <color
          rgba="0 1 0 1" />
      </material>
    </visual>
    <collision>
      <origin
        xyz="0 0 0"
        rpy="0 0 0" />
      <geometry>
        <mesh
          filename="package://robot_sim/meshes/base_link.STL" />
      </geometry>
    </collision>
  </link>
  <link
    name="r_hip">
    <inertial>
      <origin
        xyz="0.09809 2.498E-16 0.012449"
        rpy="0 0 0" />
      <mass
        value="0.086725" />
      <inertia
        ixx="5.1849E-06"
        ixy="-3.475E-19"
        ixz="-4.3335E-07"
        iyy="0.00033731"
        iyz="7.43E-21"
        izz="0.00033778" />
    </inertial>
    <visual>
      <origin
        xyz="0 0 0"
        rpy="0 0 0" />
      <geometry>
        <mesh
          filename="package://robot_sim/meshes/r_hip.STL" />
      </geometry>
      <material
        name="orange">
        <color
          rgba="1 0.65 0 1" />
      </material>
    </visual>
    <collision>
      <origin
        xyz="0 0 0"
        rpy="0 0 0" />
      <geometry>
        <mesh
          filename="package://robot_sim/meshes/r_hip.STL" />
      </geometry>
    </collision>
  </link>
  <joint
    name="base_rhip"
    type="continuous">
    <origin
      xyz="0 -0.095 0"
      rpy="1.5708 0.75994 0" />
    <parent
      link="base_link" />
    <child
      link="r_hip" />
    <axis
      xyz="0 0 1" />
  </joint>
  <link
    name="r_shank">
    <inertial>
      <origin
        xyz="0.058363 2.7756E-17 0.0075"
        rpy="0 0 0" />
      <mass
        value="0.11872" />
      <inertia
        ixx="7.0743E-06"
        ixy="-7.6656E-20"
        ixz="-6.6548E-18"
        iyy="0.00085901"
        iyz="1.3221E-21"
        izz="0.00085972" />
    </inertial>
    <visual>
      <origin
        xyz="0 0 0"
        rpy="0 0 0" />
      <geometry>
        <mesh
          filename="package://robot_sim/meshes/r_shank.STL" />
      </geometry>
      <material
        name="orange">
        <color
          rgba="1 0.65 0 1" />
      </material>
    </visual>
    <collision>
      <origin
        xyz="0 0 0"
        rpy="0 0 0" />
      <geometry>
        <mesh
          filename="package://robot_sim/meshes/r_shank.STL" />
      </geometry>
    </collision>
  </link>
  <joint
    name="r_hip_shank"
    type="continuous">
    <origin
      xyz="0.2 0 0.01"
      rpy="0 0 -1.8916" />
    <parent
      link="r_hip" />
    <child
      link="r_shank" />
    <axis
      xyz="0 0 -1" />
  </joint>
  <link
    name="r_wheel">
    <inertial>
      <origin
        xyz="2.6368E-16 1.3878E-17 0.024926"
        rpy="0 0 0" />
      <mass
        value="0.15143" />
      <inertia
        ixx="9.9483E-05"
        ixy="-1.8412E-34"
        ixz="9.4517E-19"
        iyy="9.9483E-05"
        iyz="4.5476E-21"
        izz="0.0001885" />
    </inertial>
    <visual>
      <origin
        xyz="0 0 0"
        rpy="0 0 0" />
      <geometry>
        <mesh
          filename="package://robot_sim/meshes/r_wheel.STL" />
      </geometry>
      <material
        name="black">
        <color
          rgba="0 0 0 1" />
      </material>
    </visual>
    <collision>
      <origin
        xyz="0 0 0"
        rpy="0 0 0" />
      <geometry>
        <mesh
          filename="package://robot_sim/meshes/r_wheel.STL" />
      </geometry>
    </collision>
  </link>
  <joint
    name="r_shank_wheel"
    type="continuous">
    <origin
      xyz="0.2 0 0"
      rpy="0 0 2.65150384709565" />
    <parent
      link="r_shank" />
    <child
      link="r_wheel" />
    <axis
      xyz="0 0 1" />
  </joint>
  <link
    name="r_r">
    <inertial>
      <origin
        xyz="0.025 -1.3878E-17 0.00125"
        rpy="0 0 0" />
      <mass
        value="0.006129" />
      <inertia
        ixx="2.0758E-07"
        ixy="8.2718E-22"
        ixz="1.3073E-20"
        iyy="2.1215E-06"
        iyz="-1.0061E-21"
        izz="2.3227E-06" />
    </inertial>
    <visual>
      <origin
        xyz="0 0 0"
        rpy="0 0 0" />
      <geometry>
        <mesh
          filename="package://robot_sim/meshes/r_r.STL" />
      </geometry>
      <material
        name="blue">
        <color
          rgba="0 0 1 1" />
      </material>
    </visual>
    <collision>
      <origin
        xyz="0 0 0"
        rpy="0 0 0" />
      <geometry>
        <mesh
          filename="package://robot_sim/meshes/r_r.STL" />
      </geometry>
    </collision>
  </link>
  <joint
    name="r_hip_r"
    type="continuous">
    <origin
      xyz="0 0 0.0125000000000005"
      rpy="0 0 1.43413627566753" />
    <parent
      link="r_hip" />
    <child
      link="r_r" />
    <axis
      xyz="0 0 1" />
  </joint>
  <link
    name="r_l">
    <inertial>
      <origin
        xyz="0.10794 -8.3267E-17 0.0012266"
        rpy="0 0 0" />
      <mass
        value="0.023571" />
      <inertia
        ixx="7.8625E-07"
        ixy="5.0293E-21"
        ixz="-5.9607E-08"
        iyy="0.00010916"
        iyz="-1.1659E-22"
        izz="0.00010992" />
    </inertial>
    <visual>
      <origin
        xyz="0 0 0"
        rpy="0 0 0" />
      <geometry>
        <mesh
          filename="package://robot_sim/meshes/r_l.STL" />
      </geometry>
      <material
        name="blue">
        <color
          rgba="0 0 1 1" />
      </material>
    </visual>
    <collision>
      <origin
        xyz="0 0 0"
        rpy="0 0 0" />
      <geometry>
        <mesh
          filename="package://robot_sim/meshes/r_l.STL" />
      </geometry>
    </collision>
  </link>
  <joint
    name="r_r_l"
    type="continuous">
    <origin
      xyz="0.05 0 0.0025"
      rpy="0 0 -1.3139" />
    <parent
      link="r_r" />
    <child
      link="r_l" />
    <axis
      xyz="0 0 -1" />
  </joint>
  <link
    name="l_hip">
    <inertial>
      <origin
        xyz="0.09809 9.3814E-15 0.012449"
        rpy="0 0 0" />
      <mass
        value="0.086725" />
      <inertia
        ixx="5.1849E-06"
        ixy="8.8727E-20"
        ixz="-4.3335E-07"
        iyy="0.00033731"
        iyz="1.0855E-21"
        izz="0.00033778" />
    </inertial>
    <visual>
      <origin
        xyz="0 0 0"
        rpy="0 0 0" />
      <geometry>
        <mesh
          filename="package://robot_sim/meshes/l_hip.STL" />
      </geometry>
      <material
        name="orange">
        <color
          rgba="1 0.65 0 1" />
      </material>
    </visual>
    <collision>
      <origin
        xyz="0 0 0"
        rpy="0 0 0" />
      <geometry>
        <mesh
          filename="package://robot_sim/meshes/l_hip.STL" />
      </geometry>
    </collision>
  </link>
  <joint
    name="base_lhip"
    type="continuous">
    <origin
      xyz="0 0.0949999999999995 0"
      rpy="-1.57079632679489 0.759938086259067 0" />
    <parent
      link="base_link" />
    <child
      link="l_hip" />
    <axis
      xyz="0 0 1" />
  </joint>
  <link
    name="l_shank">
    <inertial>
      <origin
        xyz="0.058363 -1.199E-13 0.0075"
        rpy="0 0 0" />
      <mass
        value="0.11872" />
      <inertia
        ixx="7.0743E-06"
        ixy="8.58E-16"
        ixz="6.4725E-18"
        iyy="0.00085901"
        iyz="1.1859E-20"
        izz="0.00085972" />
    </inertial>
    <visual>
      <origin
        xyz="0 0 0"
        rpy="0 0 0" />
      <geometry>
        <mesh
          filename="package://robot_sim/meshes/l_shank.STL" />
      </geometry>
      <material
        name="orange">
        <color
          rgba="1 0.65 0 1" />
      </material>
    </visual>
    <collision>
      <origin
        xyz="0 0 0"
        rpy="0 0 0" />
      <geometry>
        <mesh
          filename="package://robot_sim/meshes/l_shank.STL" />
      </geometry>
    </collision>
  </link>
  <joint
    name="l_hip_shank"
    type="continuous">
    <origin
      xyz="0.2 0 0.0100000000000024"
      rpy="0 0 1.89156576083605" />
    <parent
      link="l_hip" />
    <child
      link="l_shank" />
    <axis
      xyz="0 0 -1" />
  </joint>
  <link
    name="l_wheel">
    <inertial>
      <origin
        xyz="1.5261E-13 5.0931E-13 0.024926"
        rpy="0 0 0" />
      <mass
        value="0.15143" />
      <inertia
        ixx="9.9483E-05"
        ixy="5.1272E-34"
        ixz="-9.329E-19"
        iyy="9.9483E-05"
        iyz="-6.0938E-20"
        izz="0.0001885" />
    </inertial>
    <visual>
      <origin
        xyz="0 0 0"
        rpy="0 0 0" />
      <geometry>
        <mesh
          filename="package://robot_sim/meshes/l_wheel.STL" />
      </geometry>
      <material
        name="black">
        <color
          rgba="0 0 0 1" />
      </material>
    </visual>
    <collision>
      <origin
        xyz="0 0 0"
        rpy="0 0 0" />
      <geometry>
        <mesh
          filename="package://robot_sim/meshes/l_wheel.STL" />
      </geometry>
    </collision>
  </link>
  <joint
    name="l_shank_wheel"
    type="continuous">
    <origin
      xyz="0.199999999999968 0 0"
      rpy="0 0 -2.65150384709512" />
    <parent
      link="l_shank" />
    <child
      link="l_wheel" />
    <axis
      xyz="0 0 1" />
  </joint>
  <link
    name="l_r">
    <inertial>
      <origin
        xyz="0.025 -3.4361E-14 0.00125"
        rpy="0 0 0" />
      <mass
        value="0.006129" />
      <inertia
        ixx="2.0758E-07"
        ixy="3.3827E-18"
        ixz="-1.2363E-20"
        iyy="2.1215E-06"
        iyz="-7.3986E-22"
        izz="2.3227E-06" />
    </inertial>
    <visual>
      <origin
        xyz="0 0 0"
        rpy="0 0 0" />
      <geometry>
        <mesh
          filename="package://robot_sim/meshes/l_r.STL" />
      </geometry>
      <material
        name="blue">
        <color
          rgba="0 0 1 1" />
      </material>
    </visual>
    <collision>
      <origin
        xyz="0 0 0"
        rpy="0 0 0" />
      <geometry>
        <mesh
          filename="package://robot_sim/meshes/l_r.STL" />
      </geometry>
    </collision>
  </link>
  <joint
    name="l_hip_r"
    type="continuous">
    <origin
      xyz="0 0 0.0150000000000004"
      rpy="0 0 -1.43413627566782" />
    <parent
      link="l_hip" />
    <child
      link="l_r" />
    <axis
      xyz="0 0 1" />
  </joint>
  <link
    name="l_l">
    <inertial>
      <origin
        xyz="0.10794 -3.475E-14 0.0012266"
        rpy="0 0 0" />
      <mass
        value="0.023571" />
      <inertia
        ixx="7.8625E-07"
        ixy="-1.5411E-19"
        ixz="-5.9607E-08"
        iyy="0.00010916"
        iyz="6.5356E-23"
        izz="0.00010992" />
    </inertial>
    <visual>
      <origin
        xyz="0 0 0"
        rpy="0 0 0" />
      <geometry>
        <mesh
          filename="package://robot_sim/meshes/l_l.STL" />
      </geometry>
      <material
        name="blue">
        <color
          rgba="0 0 1 1" />
      </material>
    </visual>
    <collision>
      <origin
        xyz="0 0 0"
        rpy="0 0 0" />
      <geometry>
        <mesh
          filename="package://robot_sim/meshes/l_l.STL" />
      </geometry>
    </collision>
  </link>
  <joint
    name="l_r_l"
    type="continuous">
    <origin
      xyz="0.05 0 0.0025"
      rpy="0 0 1.3139" />
    <parent
      link="l_r" />
    <child
      link="l_l" />
    <axis
      xyz="0 0 -1" />
  </joint>
  <!-- Correct origin of joints -->
  <joint
    name="r_shank_L"
    type="continuous">
    <origin
      xyz="0.05 0 0.0025"
      rpy="0 0 -1.3139" />
    <parent
      link="r_shank" />
    <child
      link="r_l" />
    <axis
      xyz="0 0 -1" />
  </joint>
  <joint
    name="l_shank_L"
    type="continuous">
    <origin
      xyz="0.05 0 0.0025"
      rpy="0 0 1.3139" />
    <parent
      link="l_shank" />
    <child
      link="l_l" />
    <axis
      xyz="0 0 -1" />
  </joint>
</robot>