<sdf version='1.6'>
  <model name='robot_sim'>
    <!--link name="dummy">
      <inertial>
        <pose frame=''>0 0 0 0 -0 0</pose>
        <mass>0.0044532</mass>
        <inertia>
          <ixx>0.0044532</ixx>
          <ixy>0.0044532</ixy>
          <ixz>0.0044532</ixz>
          <iyy>0.0017162</iyy>
          <iyz>0.0044532</iyz>
          <izz>0.0052108</izz>
        </inertia>
      </inertial>
    </link-->
    <link name='base_link'>
      <pose frame=''>0 0 0 0 -0 0</pose>
      <inertial>
        <pose frame=''>-0.003429 -0 0.006897 0 -0 0</pose>
        <mass>1.0017</mass>
        <inertia>
          <ixx>0.0044532</ixx>
          <ixy>2.8047e-17</ixy>
          <ixz>1.2735e-05</ixz>
          <iyy>0.0017162</iyy>
          <iyz>-1.2345e-17</iyz>
          <izz>0.0052108</izz>
        </inertia>
      </inertial>
      <collision name='base_link_collision'>
        <pose frame=''>0 0 0 0 -0 0</pose>
        <geometry>
          <mesh>
            <scale>1 1 1</scale>
            <uri>model://robot_sim/meshes/base_link.STL</uri>
          </mesh>
        </geometry>
      </collision>
      <visual name='base_link_visual'>
        <pose frame=''>0 0 0 0 -0 0</pose>
        <geometry>
          <mesh>
            <scale>1 1 1</scale>
            <uri>model://robot_sim/meshes/base_link.STL</uri>
          </mesh>
        </geometry>
      </visual>
    </link>
    <!--joint name="dummy_joint" type="floating">
     <parent>dummy</parent>
     <child>base_link</child>
   </joint-->
    <link name='l_hip'>
      <pose frame=''>0 0.095 0 -1.5708 0.759938 -0</pose>
      <inertial>
        <pose frame=''>0.09809 0 0.012449 0 -0 0</pose>
        <mass>0.086725</mass>
        <inertia>
          <ixx>5.1849e-06</ixx>
          <ixy>8.8727e-20</ixy>
          <ixz>-4.3335e-07</ixz>
          <iyy>0.00033731</iyy>
          <iyz>1.0855e-21</iyz>
          <izz>0.00033778</izz>
        </inertia>
      </inertial>
      <collision name='l_hip_collision'>
        <pose frame=''>0 0 0 0 -0 0</pose>
        <geometry>
          <mesh>
            <scale>1 1 1</scale>
            <uri>model://robot_sim/meshes/l_hip.STL</uri>
          </mesh>
        </geometry>
      </collision>
      <visual name='l_hip_visual'>
        <pose frame=''>0 0 0 0 -0 0</pose>
        <geometry>
          <mesh>
            <scale>1 1 1</scale>
            <uri>model://robot_sim/meshes/l_hip.STL</uri>
          </mesh>
        </geometry>
      </visual>
    </link>
    <joint name='base_lhip' type='revolute'>
      <child>l_hip</child>
      <parent>base_link</parent>
      <axis>
        <xyz>0 1 0</xyz>
        <limit>
          <lower>-1e+16</lower>
          <upper>1e+16</upper>
        </limit>
        <dynamics>
          <spring_reference>0</spring_reference>
          <spring_stiffness>0</spring_stiffness>
        </dynamics>
        <use_parent_model_frame>1</use_parent_model_frame>
      </axis>
    </joint>
    <link name='l_r'>
      <pose frame=''>0 0.11 0 -1.5708 -0.674198 -0</pose>
      <inertial>
        <pose frame=''>0.025 -0 0.00125 0 -0 0</pose>
        <mass>0.006129</mass>
        <inertia>
          <ixx>2.0758e-07</ixx>
          <ixy>3.3827e-18</ixy>
          <ixz>-1.2363e-20</ixz>
          <iyy>2.1215e-06</iyy>
          <iyz>-7.3986e-22</iyz>
          <izz>2.3227e-06</izz>
        </inertia>
      </inertial>
      <collision name='l_r_collision'>
        <pose frame=''>0 0 0 0 -0 0</pose>
        <geometry>
          <mesh>
            <scale>1 1 1</scale>
            <uri>model://robot_sim/meshes/l_r.STL</uri>
          </mesh>
        </geometry>
      </collision>
      <visual name='l_r_visual'>
        <pose frame=''>0 0 0 0 -0 0</pose>
        <geometry>
          <mesh>
            <scale>1 1 1</scale>
            <uri>model://robot_sim/meshes/l_r.STL</uri>
          </mesh>
        </geometry>
      </visual>
    </link>
    <joint name='l_hip_r' type='revolute'>
      <child>l_r</child>
      <parent>l_hip</parent>
      <axis>
        <xyz>0 1 0</xyz>
        <limit>
          <lower>-1e+16</lower>
          <upper>1e+16</upper>
        </limit>
        <dynamics>
          <spring_reference>0</spring_reference>
          <spring_stiffness>0</spring_stiffness>
        </dynamics>
        <use_parent_model_frame>1</use_parent_model_frame>
      </axis>
    </joint>
    <link name='l_l'>
      <pose frame=''>0.03906 0.1125 0.031214 -1.5708 0.639702 -0</pose>
      <inertial>
        <pose frame=''>0.10794 -0 0.001227 0 -0 0</pose>
        <mass>0.023571</mass>
        <inertia>
          <ixx>7.8625e-07</ixx>
          <ixy>-1.5411e-19</ixy>
          <ixz>-5.9607e-08</ixz>
          <iyy>0.00010916</iyy>
          <iyz>6.5356e-23</iyz>
          <izz>0.00010992</izz>
        </inertia>
      </inertial>
      <collision name='l_l_collision'>
        <pose frame=''>0 0 0 0 -0 0</pose>
        <geometry>
          <mesh>
            <scale>1 1 1</scale>
            <uri>model://robot_sim/meshes/l_l.STL</uri>
          </mesh>
        </geometry>
      </collision>
      <visual name='l_l_visual'>
        <pose frame=''>0 0 0 0 -0 0</pose>
        <geometry>
          <mesh>
            <scale>1 1 1</scale>
            <uri>model://robot_sim/meshes/l_l.STL</uri>
          </mesh>
        </geometry>
      </visual>
    </link>
    <joint name='l_r_l' type='revolute'>
      <child>l_l</child>
      <parent>l_r</parent>
      <axis>
        <xyz>-0 -1 -0</xyz>
        <limit>
          <lower>-1e+16</lower>
          <upper>1e+16</upper>
        </limit>
        <dynamics>
          <spring_reference>0</spring_reference>
          <spring_stiffness>0</spring_stiffness>
        </dynamics>
        <use_parent_model_frame>1</use_parent_model_frame>
      </axis>
    </joint>
    <link name='l_shank'>
      <pose frame=''>0.144976 0.105 -0.137775 1.5708 0.490089 3.14159</pose>
      <inertial>
        <pose frame=''>0.058363 -0 0.0075 0 -0 0</pose>
        <mass>0.11872</mass>
        <inertia>
          <ixx>7.0743e-06</ixx>
          <ixy>8.58e-16</ixy>
          <ixz>6.4725e-18</ixz>
          <iyy>0.00085901</iyy>
          <iyz>1.1859e-20</iyz>
          <izz>0.00085972</izz>
        </inertia>
      </inertial>
      <collision name='l_shank_collision'>
        <pose frame=''>0 0 0 0 -0 0</pose>
        <geometry>
          <mesh>
            <scale>1 1 1</scale>
            <uri>model://robot_sim/meshes/l_shank.STL</uri>
          </mesh>
        </geometry>
      </collision>
      <visual name='l_shank_visual'>
        <pose frame=''>0 0 0 0 -0 0</pose>
        <geometry>
          <mesh>
            <scale>1 1 1</scale>
            <uri>model://robot_sim/meshes/l_shank.STL</uri>
          </mesh>
        </geometry>
      </visual>
    </link>
    <joint name='l_hip_shank' type='revolute'>
      <child>l_shank</child>
      <parent>l_hip</parent>
      <axis>
        <xyz>-0 -1 -0</xyz>
        <limit>
          <lower>-1e+16</lower>
          <upper>1e+16</upper>
        </limit>
        <dynamics>
          <spring_reference>0</spring_reference>
          <spring_stiffness>0</spring_stiffness>
        </dynamics>
        <use_parent_model_frame>1</use_parent_model_frame>
      </axis>
    </joint>
    <link name='l_wheel'>
      <pose frame=''>-0.031482 0.105 -0.231916 -1.5708 -0 -0</pose>
      <inertial>
        <pose frame=''>0 0 0.024926 0 -0 0</pose>
        <mass>0.15143</mass>
        <inertia>
          <ixx>9.9483e-05</ixx>
          <ixy>5.1272e-34</ixy>
          <ixz>-9.329e-19</ixz>
          <iyy>9.9483e-05</iyy>
          <iyz>-6.0938e-20</iyz>
          <izz>0.0001885</izz>
        </inertia>
      </inertial>
      <collision name='l_wheel_collision'>
        <pose frame=''>0 0 0 0 -0 0</pose>
        <geometry>
          <mesh>
            <scale>1 1 1</scale>
            <uri>model://robot_sim/meshes/l_wheel.STL</uri>
          </mesh>
        </geometry>
      </collision>
      <visual name='l_wheel_visual'>
        <pose frame=''>0 0 0 0 -0 0</pose>
        <geometry>
          <mesh>
            <scale>1 1 1</scale>
            <uri>model://robot_sim/meshes/l_wheel.STL</uri>
          </mesh>
        </geometry>
      </visual>
    </link>
    <joint name='l_shank_wheel' type='revolute'>
      <child>l_wheel</child>
      <parent>l_shank</parent>
      <axis>
        <xyz>0 1 0</xyz>
        <limit>
          <lower>-1e+16</lower>
          <upper>1e+16</upper>
        </limit>
        <dynamics>
          <spring_reference>0</spring_reference>
          <spring_stiffness>0</spring_stiffness>
        </dynamics>
        <use_parent_model_frame>1</use_parent_model_frame>
      </axis>
    </joint>
    <link name='r_hip'>
      <pose frame=''>0 -0.095 0 1.5708 0.75994 0</pose>
      <inertial>
        <pose frame=''>0.09809 0 0.012449 0 -0 0</pose>
        <mass>0.086725</mass>
        <inertia>
          <ixx>5.1849e-06</ixx>
          <ixy>-3.475e-19</ixy>
          <ixz>-4.3335e-07</ixz>
          <iyy>0.00033731</iyy>
          <iyz>7.43e-21</iyz>
          <izz>0.00033778</izz>
        </inertia>
      </inertial>
      <collision name='r_hip_collision'>
        <pose frame=''>0 0 0 0 -0 0</pose>
        <geometry>
          <mesh>
            <scale>1 1 1</scale>
            <uri>model://robot_sim/meshes/r_hip.STL</uri>
          </mesh>
        </geometry>
      </collision>
      <visual name='r_hip_visual'>
        <pose frame=''>0 0 0 0 -0 0</pose>
        <geometry>
          <mesh>
            <scale>1 1 1</scale>
            <uri>model://robot_sim/meshes/r_hip.STL</uri>
          </mesh>
        </geometry>
      </visual>
    </link>
    <joint name='base_rhip' type='revolute'>
      <child>r_hip</child>
      <parent>base_link</parent>
      <axis>
        <xyz>-3e-06 -1 -3e-06</xyz>
        <limit>
          <lower>-1e+16</lower>
          <upper>1e+16</upper>
        </limit>
        <dynamics>
          <spring_reference>0</spring_reference>
          <spring_stiffness>0</spring_stiffness>
        </dynamics>
        <use_parent_model_frame>1</use_parent_model_frame>
      </axis>
    </joint>
    <link name='r_r'>
      <pose frame=''>-0 -0.1075 -0 1.5708 -0.674196 -5e-06</pose>
      <inertial>
        <pose frame=''>0.025 -0 0.00125 0 -0 0</pose>
        <mass>0.006129</mass>
        <inertia>
          <ixx>2.0758e-07</ixx>
          <ixy>8.2718e-22</ixy>
          <ixz>1.3073e-20</ixz>
          <iyy>2.1215e-06</iyy>
          <iyz>-1.0061e-21</iyz>
          <izz>2.3227e-06</izz>
        </inertia>
      </inertial>
      <collision name='r_r_collision'>
        <pose frame=''>0 0 0 0 -0 0</pose>
        <geometry>
          <mesh>
            <scale>1 1 1</scale>
            <uri>model://robot_sim/meshes/r_r.STL</uri>
          </mesh>
        </geometry>
      </collision>
      <visual name='r_r_visual'>
        <pose frame=''>0 0 0 0 -0 0</pose>
        <geometry>
          <mesh>
            <scale>1 1 1</scale>
            <uri>model://robot_sim/meshes/r_r.STL</uri>
          </mesh>
        </geometry>
      </visual>
    </link>
    <joint name='r_hip_r' type='revolute'>
      <child>r_r</child>
      <parent>r_hip</parent>
      <axis>
        <xyz>-3e-06 -1 -3e-06</xyz>
        <limit>
          <lower>-1e+16</lower>
          <upper>1e+16</upper>
        </limit>
        <dynamics>
          <spring_reference>0</spring_reference>
          <spring_stiffness>0</spring_stiffness>
        </dynamics>
        <use_parent_model_frame>1</use_parent_model_frame>
      </axis>
    </joint>
    <link name='r_l'>
      <pose frame=''>0.03906 -0.11 0.031213 1.5708 0.639704 -1e-06</pose>
      <inertial>
        <pose frame=''>0.10794 -0 0.001227 0 -0 0</pose>
        <mass>0.023571</mass>
        <inertia>
          <ixx>7.8625e-07</ixx>
          <ixy>5.0293e-21</ixy>
          <ixz>-5.9607e-08</ixz>
          <iyy>0.00010916</iyy>
          <iyz>-1.1659e-22</iyz>
          <izz>0.00010992</izz>
        </inertia>
      </inertial>
      <collision name='r_l_collision'>
        <pose frame=''>0 0 0 0 -0 0</pose>
        <geometry>
          <mesh>
            <scale>1 1 1</scale>
            <uri>model://robot_sim/meshes/r_l.STL</uri>
          </mesh>
        </geometry>
      </collision>
      <visual name='r_l_visual'>
        <pose frame=''>0 0 0 0 -0 0</pose>
        <geometry>
          <mesh>
            <scale>1 1 1</scale>
            <uri>model://robot_sim/meshes/r_l.STL</uri>
          </mesh>
        </geometry>
      </visual>
    </link>
    <joint name='r_r_l' type='revolute'>
      <child>r_l</child>
      <parent>r_r</parent>
      <axis>
        <xyz>3e-06 1 3e-06</xyz>
        <limit>
          <lower>-1e+16</lower>
          <upper>1e+16</upper>
        </limit>
        <dynamics>
          <spring_reference>0</spring_reference>
          <spring_stiffness>0</spring_stiffness>
        </dynamics>
        <use_parent_model_frame>1</use_parent_model_frame>
      </axis>
    </joint>
    <link name='r_shank'>
      <pose frame=''>0.144975 -0.105 -0.137776 -1.5708 0.490053 3.14159</pose>
      <inertial>
        <pose frame=''>0.058363 0 0.0075 0 -0 0</pose>
        <mass>0.11872</mass>
        <inertia>
          <ixx>7.0743e-06</ixx>
          <ixy>-7.6656e-20</ixy>
          <ixz>-6.6548e-18</ixz>
          <iyy>0.00085901</iyy>
          <iyz>1.3221e-21</iyz>
          <izz>0.00085972</izz>
        </inertia>
      </inertial>
      <collision name='r_shank_collision'>
        <pose frame=''>0 0 0 0 -0 0</pose>
        <geometry>
          <mesh>
            <scale>1 1 1</scale>
            <uri>model://robot_sim/meshes/r_shank.STL</uri>
          </mesh>
        </geometry>
      </collision>
      <visual name='r_shank_visual'>
        <pose frame=''>0 0 0 0 -0 0</pose>
        <geometry>
          <mesh>
            <scale>1 1 1</scale>
            <uri>model://robot_sim/meshes/r_shank.STL</uri>
          </mesh>
        </geometry>
      </visual>
    </link>
    <joint name='r_hip_shank' type='revolute'>
      <child>r_shank</child>
      <parent>r_hip</parent>
      <axis>
        <xyz>3e-06 1 3e-06</xyz>
        <limit>
          <lower>-1e+16</lower>
          <upper>1e+16</upper>
        </limit>
        <dynamics>
          <spring_reference>0</spring_reference>
          <spring_stiffness>0</spring_stiffness>
        </dynamics>
        <use_parent_model_frame>1</use_parent_model_frame>
      </axis>
    </joint>
    <link name='r_wheel'>
      <pose frame=''>-0.031486 -0.104999 -0.23191 1.5708 3.6e-05 -3e-06</pose>
      <inertial>
        <pose frame=''>0 0 0.024926 0 -0 0</pose>
        <mass>0.15143</mass>
        <inertia>
          <ixx>9.9483e-05</ixx>
          <ixy>-1.8412e-34</ixy>
          <ixz>9.4517e-19</ixz>
          <iyy>9.9483e-05</iyy>
          <iyz>4.5476e-21</iyz>
          <izz>0.0001885</izz>
        </inertia>
      </inertial>
      <collision name='r_wheel_collision'>
        <pose frame=''>0 0 0 0 -0 0</pose>
        <geometry>
          <mesh>
            <scale>1 1 1</scale>
            <uri>model://robot_sim/meshes/r_wheel.STL</uri>
          </mesh>
        </geometry>
      </collision>
      <visual name='r_wheel_visual'>
        <pose frame=''>0 0 0 0 -0 0</pose>
        <geometry>
          <mesh>
            <scale>1 1 1</scale>
            <uri>model://robot_sim/meshes/r_wheel.STL</uri>
          </mesh>
        </geometry>
      </visual>
    </link>
    <joint name='r_shank_wheel' type='revolute'>
      <child>r_wheel</child>
      <parent>r_shank</parent>
      <axis>
        <xyz>-3e-06 -1 -3e-06</xyz>
        <limit>
          <lower>-1e+16</lower>
          <upper>1e+16</upper>
        </limit>
        <dynamics>
          <spring_reference>0</spring_reference>
          <spring_stiffness>0</spring_stiffness>
        </dynamics>
        <use_parent_model_frame>1</use_parent_model_frame>
      </axis>
    </joint>

    <static>0</static>

    <joint name='l_shank_l' type='revolute'>
      <pose frame=''>-0.08 0 0 0 0 0</pose>
      <axis>
        <xyz>0 -1 0</xyz>
        <limit>
          <lower>-1e+16</lower>
          <upper>1e+16</upper>
        </limit>
        <dynamics>
          <spring_reference>0</spring_reference>
          <spring_stiffness>0</spring_stiffness>
        </dynamics>
        <use_parent_model_frame>1</use_parent_model_frame>
      </axis>
      <parent>l_l</parent>
      <child>l_shank</child>
    </joint>

    <joint name='r_shank_l' type='revolute'>
      <pose frame=''>-0.08 0 0 0 0 0</pose>
      <axis>
        <xyz>0 1 0</xyz>
        <limit>
          <lower>-1e+16</lower>
          <upper>1e+16</upper>
        </limit>
        <dynamics>
          <spring_reference>0</spring_reference>
          <spring_stiffness>0</spring_stiffness>
        </dynamics>
        <use_parent_model_frame>1</use_parent_model_frame>
      </axis>
      <parent>r_l</parent>
      <child>r_shank</child>
    </joint>

    <plugin name="gazebo_ros_control" filename="libgazebo_ros_control.so">
      <robotNamespace>/</robotNamespace>
      <robotSimType>gazebo_ros_control/DefaultRobotHWSim</robotSimType>
    </plugin>

    <plugin name="imu_plugin" filename="libgazebo_ros_imu.so">
      <alwaysOn>true</alwaysOn>
      <bodyName>base_link</bodyName>
      <topicName>imu</topicName>
      <serviceName>imu_service</serviceName>
      <gaussianNoise>0.0</gaussianNoise>
      <updateRate>50.0</updateRate>
    </plugin>

    <!-- Loading Gazebo_ros_control -->
    <!--gazebo>
        <plugin name="gazebo_ros_control" filename="libgazebo_ros_control.so"/>
          <robotNamespace>/</robotNamespace>
    </gazebo-->
    
  </model>

</sdf>
